[2024-09-05 16:39:38 +0200] [79229] [INFO] Starting gunicorn 23.0.0
[2024-09-05 16:39:38 +0200] [79229] [INFO] Listening at: http://127.0.0.1:8000 (79229)
[2024-09-05 16:39:38 +0200] [79229] [INFO] Using worker: sync
[2024-09-05 16:39:38 +0200] [79243] [INFO] Booting worker with pid: 79243
[2024-09-05 16:39:38 +0200] [79243] [ERROR] Exception in worker process
Traceback (most recent call last):
  File "/Users/yoadbarok/Dev/data_practice/venv/lib/python3.12/site-packages/gunicorn/arbiter.py", line 608, in spawn_worker
    worker.init_process()
  File "/Users/yoadbarok/Dev/data_practice/venv/lib/python3.12/site-packages/gunicorn/workers/base.py", line 135, in init_process
    self.load_wsgi()
  File "/Users/yoadbarok/Dev/data_practice/venv/lib/python3.12/site-packages/gunicorn/workers/base.py", line 147, in load_wsgi
    self.wsgi = self.app.wsgi()
                ^^^^^^^^^^^^^^^
  File "/Users/yoadbarok/Dev/data_practice/venv/lib/python3.12/site-packages/gunicorn/app/base.py", line 66, in wsgi
    self.callable = self.load()
                    ^^^^^^^^^^^
  File "/Users/yoadbarok/Dev/data_practice/venv/lib/python3.12/site-packages/gunicorn/app/wsgiapp.py", line 57, in load
    return self.load_wsgiapp()
           ^^^^^^^^^^^^^^^^^^^
  File "/Users/yoadbarok/Dev/data_practice/venv/lib/python3.12/site-packages/gunicorn/app/wsgiapp.py", line 47, in load_wsgiapp
    return util.import_app(self.app_uri)
           ^^^^^^^^^^^^^^^^^^^^^^^^^^^^^
  File "/Users/yoadbarok/Dev/data_practice/venv/lib/python3.12/site-packages/gunicorn/util.py", line 370, in import_app
    mod = importlib.import_module(module)
          ^^^^^^^^^^^^^^^^^^^^^^^^^^^^^^^
  File "/opt/anaconda3/lib/python3.12/importlib/__init__.py", line 90, in import_module
    return _bootstrap._gcd_import(name[level:], package, level)
           ^^^^^^^^^^^^^^^^^^^^^^^^^^^^^^^^^^^^^^^^^^^^^^^^^^^^
  File "<frozen importlib._bootstrap>", line 1387, in _gcd_import
  File "<frozen importlib._bootstrap>", line 1360, in _find_and_load
  File "<frozen importlib._bootstrap>", line 1324, in _find_and_load_unlocked
ModuleNotFoundError: No module named 'app_py'
[2024-09-05 16:39:38 +0200] [79243] [INFO] Worker exiting (pid: 79243)
[2024-09-05 16:39:38 +0200] [79229] [ERROR] Worker (pid:79243) exited with code 3
[2024-09-05 16:39:38 +0200] [79229] [ERROR] Shutting down: Master
[2024-09-05 16:39:38 +0200] [79229] [ERROR] Reason: Worker failed to boot.
[2024-09-05 16:39:50 +0200] [79481] [INFO] Starting gunicorn 23.0.0
[2024-09-05 16:39:50 +0200] [79481] [INFO] Listening at: http://127.0.0.1:8000 (79481)
[2024-09-05 16:39:50 +0200] [79481] [INFO] Using worker: sync
[2024-09-05 16:39:50 +0200] [79482] [INFO] Booting worker with pid: 79482
[2024-09-05 16:39:50 +0200] [79482] [ERROR] Exception in worker process
Traceback (most recent call last):
  File "/Users/yoadbarok/Dev/data_practice/venv/lib/python3.12/site-packages/gunicorn/arbiter.py", line 608, in spawn_worker
    worker.init_process()
  File "/Users/yoadbarok/Dev/data_practice/venv/lib/python3.12/site-packages/gunicorn/workers/base.py", line 135, in init_process
    self.load_wsgi()
  File "/Users/yoadbarok/Dev/data_practice/venv/lib/python3.12/site-packages/gunicorn/workers/base.py", line 147, in load_wsgi
    self.wsgi = self.app.wsgi()
                ^^^^^^^^^^^^^^^
  File "/Users/yoadbarok/Dev/data_practice/venv/lib/python3.12/site-packages/gunicorn/app/base.py", line 66, in wsgi
    self.callable = self.load()
                    ^^^^^^^^^^^
  File "/Users/yoadbarok/Dev/data_practice/venv/lib/python3.12/site-packages/gunicorn/app/wsgiapp.py", line 57, in load
    return self.load_wsgiapp()
           ^^^^^^^^^^^^^^^^^^^
  File "/Users/yoadbarok/Dev/data_practice/venv/lib/python3.12/site-packages/gunicorn/app/wsgiapp.py", line 47, in load_wsgiapp
    return util.import_app(self.app_uri)
           ^^^^^^^^^^^^^^^^^^^^^^^^^^^^^
  File "/Users/yoadbarok/Dev/data_practice/venv/lib/python3.12/site-packages/gunicorn/util.py", line 370, in import_app
    mod = importlib.import_module(module)
          ^^^^^^^^^^^^^^^^^^^^^^^^^^^^^^^
  File "/opt/anaconda3/lib/python3.12/importlib/__init__.py", line 90, in import_module
    return _bootstrap._gcd_import(name[level:], package, level)
           ^^^^^^^^^^^^^^^^^^^^^^^^^^^^^^^^^^^^^^^^^^^^^^^^^^^^
  File "<frozen importlib._bootstrap>", line 1387, in _gcd_import
  File "<frozen importlib._bootstrap>", line 1360, in _find_and_load
  File "<frozen importlib._bootstrap>", line 1331, in _find_and_load_unlocked
  File "<frozen importlib._bootstrap>", line 935, in _load_unlocked
  File "<frozen importlib._bootstrap_external>", line 995, in exec_module
  File "<frozen importlib._bootstrap>", line 488, in _call_with_frames_removed
  File "/Users/yoadbarok/Dev/data_practice/src/server.py", line 4, in <module>
    from blueprints.plotting import plotting_bp
ModuleNotFoundError: No module named 'blueprints'
[2024-09-05 16:39:50 +0200] [79482] [INFO] Worker exiting (pid: 79482)
[2024-09-05 16:39:50 +0200] [79481] [ERROR] Worker (pid:79482) exited with code 3
[2024-09-05 16:39:50 +0200] [79481] [ERROR] Shutting down: Master
[2024-09-05 16:39:50 +0200] [79481] [ERROR] Reason: Worker failed to boot.
[2024-09-05 16:40:16 +0200] [80066] [INFO] Starting gunicorn 23.0.0
[2024-09-05 16:40:16 +0200] [80066] [INFO] Listening at: http://127.0.0.1:8000 (80066)
[2024-09-05 16:40:16 +0200] [80066] [INFO] Using worker: sync
[2024-09-05 16:40:16 +0200] [80067] [INFO] Booting worker with pid: 80067
[2024-09-05 16:40:16 +0200] [80067] [ERROR] Exception in worker process
Traceback (most recent call last):
  File "/Users/yoadbarok/Dev/data_practice/venv/lib/python3.12/site-packages/gunicorn/arbiter.py", line 608, in spawn_worker
    worker.init_process()
  File "/Users/yoadbarok/Dev/data_practice/venv/lib/python3.12/site-packages/gunicorn/workers/base.py", line 135, in init_process
    self.load_wsgi()
  File "/Users/yoadbarok/Dev/data_practice/venv/lib/python3.12/site-packages/gunicorn/workers/base.py", line 147, in load_wsgi
    self.wsgi = self.app.wsgi()
                ^^^^^^^^^^^^^^^
  File "/Users/yoadbarok/Dev/data_practice/venv/lib/python3.12/site-packages/gunicorn/app/base.py", line 66, in wsgi
    self.callable = self.load()
                    ^^^^^^^^^^^
  File "/Users/yoadbarok/Dev/data_practice/venv/lib/python3.12/site-packages/gunicorn/app/wsgiapp.py", line 57, in load
    return self.load_wsgiapp()
           ^^^^^^^^^^^^^^^^^^^
  File "/Users/yoadbarok/Dev/data_practice/venv/lib/python3.12/site-packages/gunicorn/app/wsgiapp.py", line 47, in load_wsgiapp
    return util.import_app(self.app_uri)
           ^^^^^^^^^^^^^^^^^^^^^^^^^^^^^
  File "/Users/yoadbarok/Dev/data_practice/venv/lib/python3.12/site-packages/gunicorn/util.py", line 370, in import_app
    mod = importlib.import_module(module)
          ^^^^^^^^^^^^^^^^^^^^^^^^^^^^^^^
  File "/opt/anaconda3/lib/python3.12/importlib/__init__.py", line 90, in import_module
    return _bootstrap._gcd_import(name[level:], package, level)
           ^^^^^^^^^^^^^^^^^^^^^^^^^^^^^^^^^^^^^^^^^^^^^^^^^^^^
  File "<frozen importlib._bootstrap>", line 1387, in _gcd_import
  File "<frozen importlib._bootstrap>", line 1360, in _find_and_load
  File "<frozen importlib._bootstrap>", line 1324, in _find_and_load_unlocked
ModuleNotFoundError: No module named 'server'
[2024-09-05 16:40:16 +0200] [80067] [INFO] Worker exiting (pid: 80067)
[2024-09-05 16:40:16 +0200] [80066] [ERROR] Worker (pid:80067) exited with code 3
[2024-09-05 16:40:16 +0200] [80066] [ERROR] Shutting down: Master
[2024-09-05 16:40:16 +0200] [80066] [ERROR] Reason: Worker failed to boot.
